{
 "cells": [
  {
   "cell_type": "code",
   "execution_count": 1,
   "metadata": {},
   "outputs": [],
   "source": [
    "from tensorflow.keras.models import load_model"
   ]
  },
  {
   "cell_type": "code",
   "execution_count": 2,
   "metadata": {},
   "outputs": [],
   "source": [
    "import numpy as np"
   ]
  },
  {
   "cell_type": "code",
   "execution_count": 3,
   "metadata": {},
   "outputs": [],
   "source": [
    "import pandas as pd"
   ]
  },
  {
   "cell_type": "code",
   "execution_count": 4,
   "metadata": {},
   "outputs": [],
   "source": [
    "model = load_model(\"cnn_cd.h5\")"
   ]
  },
  {
   "cell_type": "code",
   "execution_count": 5,
   "metadata": {},
   "outputs": [],
   "source": [
    "import cv2"
   ]
  },
  {
   "cell_type": "code",
   "execution_count": 6,
   "metadata": {},
   "outputs": [],
   "source": [
    "import matplotlib.pyplot as plt"
   ]
  },
  {
   "cell_type": "code",
   "execution_count": 7,
   "metadata": {},
   "outputs": [],
   "source": [
    "def predict(image_path):\n",
    "    image = cv2.imread(image_path)\n",
    "    image = cv2.cvtColor(image, cv2.COLOR_BGR2RGB)\n",
    "    image = cv2.resize(image,(128,128))\n",
    "    image = image * (1.0/255.0)\n",
    "    image = np.array([image])\n",
    "    y_pred = model.predict(image, verbose = 0)\n",
    "    y_pred = y_pred > 0.5\n",
    "    y_pred = y_pred.astype(\"int\")[0][0]\n",
    "    classes = [\"Cat\",\"Dog\"]\n",
    "    \n",
    "    return classes[y_pred]"
   ]
  },
  {
   "cell_type": "code",
   "execution_count": 13,
   "metadata": {},
   "outputs": [
    {
     "data": {
      "text/plain": [
       "'Dog'"
      ]
     },
     "execution_count": 13,
     "metadata": {},
     "output_type": "execute_result"
    }
   ],
   "source": [
    "predict(r\"data\\img.jpg\")"
   ]
  },
  {
   "cell_type": "code",
   "execution_count": 14,
   "metadata": {},
   "outputs": [],
   "source": [
    "def predict_mutiple(image_paths_list):\n",
    "    images_array = []\n",
    "    for image_path in image_paths_list:\n",
    "        image = cv2.imread(image_path)\n",
    "        image = cv2.cvtColor(image, cv2.COLOR_BGR2RGB)\n",
    "        image = cv2.resize(image,(64,64))\n",
    "        image = image * (1.0/255.0)\n",
    "        images_array.append(image)\n",
    "    images_array = np.array(images_array)\n",
    "    \n",
    "    y_pred = model.predict(images_array, verbose = 0)\n",
    "    \n",
    "    y_pred = y_pred > 0.5\n",
    "    y_pred = y_pred.astype(\"int\")\n",
    "    result = pd.DataFrame(columns = [\"Path\",\"Prediction\"])\n",
    "    result[\"Path\"] = image_paths_list\n",
    "    result[\"Prediction\"] = y_pred\n",
    "    result[\"Prediction\"].replace({1:\"Dog\",0:\"Cat\"}, inplace = True)\n",
    "    return result"
   ]
  },
  {
   "cell_type": "code",
   "execution_count": 15,
   "metadata": {},
   "outputs": [],
   "source": [
    "import glob"
   ]
  },
  {
   "cell_type": "code",
   "execution_count": 16,
   "metadata": {},
   "outputs": [],
   "source": [
    "image_paths_list =  glob.glob(r\"data\\dataset\\test_set\\cats\\*.jpg\")"
   ]
  },
  {
   "cell_type": "code",
   "execution_count": 17,
   "metadata": {},
   "outputs": [
    {
     "ename": "InvalidArgumentError",
     "evalue": "Graph execution error:\n\nDetected at node sequential/dense/Relu defined at (most recent call last):\n  File \"C:\\Users\\7240\\anaconda3\\lib\\runpy.py\", line 197, in _run_module_as_main\n\n  File \"C:\\Users\\7240\\anaconda3\\lib\\runpy.py\", line 87, in _run_code\n\n  File \"C:\\Users\\7240\\anaconda3\\lib\\site-packages\\ipykernel_launcher.py\", line 17, in <module>\n\n  File \"C:\\Users\\7240\\anaconda3\\lib\\site-packages\\traitlets\\config\\application.py\", line 846, in launch_instance\n\n  File \"C:\\Users\\7240\\anaconda3\\lib\\site-packages\\ipykernel\\kernelapp.py\", line 712, in start\n\n  File \"C:\\Users\\7240\\anaconda3\\lib\\site-packages\\tornado\\platform\\asyncio.py\", line 199, in start\n\n  File \"C:\\Users\\7240\\anaconda3\\lib\\asyncio\\base_events.py\", line 601, in run_forever\n\n  File \"C:\\Users\\7240\\anaconda3\\lib\\asyncio\\base_events.py\", line 1905, in _run_once\n\n  File \"C:\\Users\\7240\\anaconda3\\lib\\asyncio\\events.py\", line 80, in _run\n\n  File \"C:\\Users\\7240\\anaconda3\\lib\\site-packages\\ipykernel\\kernelbase.py\", line 510, in dispatch_queue\n\n  File \"C:\\Users\\7240\\anaconda3\\lib\\site-packages\\ipykernel\\kernelbase.py\", line 499, in process_one\n\n  File \"C:\\Users\\7240\\anaconda3\\lib\\site-packages\\ipykernel\\kernelbase.py\", line 406, in dispatch_shell\n\n  File \"C:\\Users\\7240\\anaconda3\\lib\\site-packages\\ipykernel\\kernelbase.py\", line 730, in execute_request\n\n  File \"C:\\Users\\7240\\anaconda3\\lib\\site-packages\\ipykernel\\ipkernel.py\", line 390, in do_execute\n\n  File \"C:\\Users\\7240\\anaconda3\\lib\\site-packages\\ipykernel\\zmqshell.py\", line 528, in run_cell\n\n  File \"C:\\Users\\7240\\anaconda3\\lib\\site-packages\\IPython\\core\\interactiveshell.py\", line 2914, in run_cell\n\n  File \"C:\\Users\\7240\\anaconda3\\lib\\site-packages\\IPython\\core\\interactiveshell.py\", line 2960, in _run_cell\n\n  File \"C:\\Users\\7240\\anaconda3\\lib\\site-packages\\IPython\\core\\async_helpers.py\", line 78, in _pseudo_sync_runner\n\n  File \"C:\\Users\\7240\\anaconda3\\lib\\site-packages\\IPython\\core\\interactiveshell.py\", line 3185, in run_cell_async\n\n  File \"C:\\Users\\7240\\anaconda3\\lib\\site-packages\\IPython\\core\\interactiveshell.py\", line 3377, in run_ast_nodes\n\n  File \"C:\\Users\\7240\\anaconda3\\lib\\site-packages\\IPython\\core\\interactiveshell.py\", line 3457, in run_code\n\n  File \"C:\\Users\\7240\\AppData\\Local\\Temp\\ipykernel_6564\\994942145.py\", line 1, in <module>\n\n  File \"C:\\Users\\7240\\AppData\\Local\\Temp\\ipykernel_6564\\3861827433.py\", line 11, in predict_mutiple\n\n  File \"C:\\Users\\7240\\anaconda3\\lib\\site-packages\\keras\\src\\utils\\traceback_utils.py\", line 65, in error_handler\n\n  File \"C:\\Users\\7240\\anaconda3\\lib\\site-packages\\keras\\src\\engine\\training.py\", line 2631, in predict\n\n  File \"C:\\Users\\7240\\anaconda3\\lib\\site-packages\\keras\\src\\engine\\training.py\", line 2416, in predict_function\n\n  File \"C:\\Users\\7240\\anaconda3\\lib\\site-packages\\keras\\src\\engine\\training.py\", line 2401, in step_function\n\n  File \"C:\\Users\\7240\\anaconda3\\lib\\site-packages\\keras\\src\\engine\\training.py\", line 2389, in run_step\n\n  File \"C:\\Users\\7240\\anaconda3\\lib\\site-packages\\keras\\src\\engine\\training.py\", line 2357, in predict_step\n\n  File \"C:\\Users\\7240\\anaconda3\\lib\\site-packages\\keras\\src\\utils\\traceback_utils.py\", line 65, in error_handler\n\n  File \"C:\\Users\\7240\\anaconda3\\lib\\site-packages\\keras\\src\\engine\\training.py\", line 589, in __call__\n\n  File \"C:\\Users\\7240\\anaconda3\\lib\\site-packages\\keras\\src\\utils\\traceback_utils.py\", line 65, in error_handler\n\n  File \"C:\\Users\\7240\\anaconda3\\lib\\site-packages\\keras\\src\\engine\\base_layer.py\", line 1149, in __call__\n\n  File \"C:\\Users\\7240\\anaconda3\\lib\\site-packages\\keras\\src\\utils\\traceback_utils.py\", line 96, in error_handler\n\n  File \"C:\\Users\\7240\\anaconda3\\lib\\site-packages\\keras\\src\\engine\\sequential.py\", line 398, in call\n\n  File \"C:\\Users\\7240\\anaconda3\\lib\\site-packages\\keras\\src\\engine\\functional.py\", line 515, in call\n\n  File \"C:\\Users\\7240\\anaconda3\\lib\\site-packages\\keras\\src\\engine\\functional.py\", line 672, in _run_internal_graph\n\n  File \"C:\\Users\\7240\\anaconda3\\lib\\site-packages\\keras\\src\\utils\\traceback_utils.py\", line 65, in error_handler\n\n  File \"C:\\Users\\7240\\anaconda3\\lib\\site-packages\\keras\\src\\engine\\base_layer.py\", line 1149, in __call__\n\n  File \"C:\\Users\\7240\\anaconda3\\lib\\site-packages\\keras\\src\\utils\\traceback_utils.py\", line 96, in error_handler\n\n  File \"C:\\Users\\7240\\anaconda3\\lib\\site-packages\\keras\\src\\layers\\core\\dense.py\", line 255, in call\n\n  File \"C:\\Users\\7240\\anaconda3\\lib\\site-packages\\keras\\src\\activations.py\", line 306, in relu\n\n  File \"C:\\Users\\7240\\anaconda3\\lib\\site-packages\\keras\\src\\backend.py\", line 5397, in relu\n\nMatrix size-incompatible: In[0]: [32,12544], In[1]: [57600,500]\n\t [[{{node sequential/dense/Relu}}]] [Op:__inference_predict_function_491]",
     "output_type": "error",
     "traceback": [
      "\u001b[1;31m---------------------------------------------------------------------------\u001b[0m",
      "\u001b[1;31mInvalidArgumentError\u001b[0m                      Traceback (most recent call last)",
      "\u001b[1;32m~\\AppData\\Local\\Temp\\ipykernel_6564\\994942145.py\u001b[0m in \u001b[0;36m<module>\u001b[1;34m\u001b[0m\n\u001b[1;32m----> 1\u001b[1;33m \u001b[0mpredict_mutiple\u001b[0m\u001b[1;33m(\u001b[0m\u001b[0mimage_paths_list\u001b[0m\u001b[1;33m)\u001b[0m\u001b[1;33m\u001b[0m\u001b[1;33m\u001b[0m\u001b[0m\n\u001b[0m",
      "\u001b[1;32m~\\AppData\\Local\\Temp\\ipykernel_6564\\3861827433.py\u001b[0m in \u001b[0;36mpredict_mutiple\u001b[1;34m(image_paths_list)\u001b[0m\n\u001b[0;32m      9\u001b[0m     \u001b[0mimages_array\u001b[0m \u001b[1;33m=\u001b[0m \u001b[0mnp\u001b[0m\u001b[1;33m.\u001b[0m\u001b[0marray\u001b[0m\u001b[1;33m(\u001b[0m\u001b[0mimages_array\u001b[0m\u001b[1;33m)\u001b[0m\u001b[1;33m\u001b[0m\u001b[1;33m\u001b[0m\u001b[0m\n\u001b[0;32m     10\u001b[0m \u001b[1;33m\u001b[0m\u001b[0m\n\u001b[1;32m---> 11\u001b[1;33m     \u001b[0my_pred\u001b[0m \u001b[1;33m=\u001b[0m \u001b[0mmodel\u001b[0m\u001b[1;33m.\u001b[0m\u001b[0mpredict\u001b[0m\u001b[1;33m(\u001b[0m\u001b[0mimages_array\u001b[0m\u001b[1;33m,\u001b[0m \u001b[0mverbose\u001b[0m \u001b[1;33m=\u001b[0m \u001b[1;36m0\u001b[0m\u001b[1;33m)\u001b[0m\u001b[1;33m\u001b[0m\u001b[1;33m\u001b[0m\u001b[0m\n\u001b[0m\u001b[0;32m     12\u001b[0m \u001b[1;33m\u001b[0m\u001b[0m\n\u001b[0;32m     13\u001b[0m     \u001b[0my_pred\u001b[0m \u001b[1;33m=\u001b[0m \u001b[0my_pred\u001b[0m \u001b[1;33m>\u001b[0m \u001b[1;36m0.5\u001b[0m\u001b[1;33m\u001b[0m\u001b[1;33m\u001b[0m\u001b[0m\n",
      "\u001b[1;32m~\\anaconda3\\lib\\site-packages\\keras\\src\\utils\\traceback_utils.py\u001b[0m in \u001b[0;36merror_handler\u001b[1;34m(*args, **kwargs)\u001b[0m\n\u001b[0;32m     68\u001b[0m             \u001b[1;31m# To get the full stack trace, call:\u001b[0m\u001b[1;33m\u001b[0m\u001b[1;33m\u001b[0m\u001b[0m\n\u001b[0;32m     69\u001b[0m             \u001b[1;31m# `tf.debugging.disable_traceback_filtering()`\u001b[0m\u001b[1;33m\u001b[0m\u001b[1;33m\u001b[0m\u001b[0m\n\u001b[1;32m---> 70\u001b[1;33m             \u001b[1;32mraise\u001b[0m \u001b[0me\u001b[0m\u001b[1;33m.\u001b[0m\u001b[0mwith_traceback\u001b[0m\u001b[1;33m(\u001b[0m\u001b[0mfiltered_tb\u001b[0m\u001b[1;33m)\u001b[0m \u001b[1;32mfrom\u001b[0m \u001b[1;32mNone\u001b[0m\u001b[1;33m\u001b[0m\u001b[1;33m\u001b[0m\u001b[0m\n\u001b[0m\u001b[0;32m     71\u001b[0m         \u001b[1;32mfinally\u001b[0m\u001b[1;33m:\u001b[0m\u001b[1;33m\u001b[0m\u001b[1;33m\u001b[0m\u001b[0m\n\u001b[0;32m     72\u001b[0m             \u001b[1;32mdel\u001b[0m \u001b[0mfiltered_tb\u001b[0m\u001b[1;33m\u001b[0m\u001b[1;33m\u001b[0m\u001b[0m\n",
      "\u001b[1;32m~\\anaconda3\\lib\\site-packages\\tensorflow\\python\\eager\\execute.py\u001b[0m in \u001b[0;36mquick_execute\u001b[1;34m(op_name, num_outputs, inputs, attrs, ctx, name)\u001b[0m\n\u001b[0;32m     58\u001b[0m         \u001b[1;32mfor\u001b[0m \u001b[0mt\u001b[0m \u001b[1;32min\u001b[0m \u001b[0minputs\u001b[0m\u001b[1;33m\u001b[0m\u001b[1;33m\u001b[0m\u001b[0m\n\u001b[0;32m     59\u001b[0m     ]\n\u001b[1;32m---> 60\u001b[1;33m     tensors = pywrap_tfe.TFE_Py_Execute(ctx._handle, device_name, op_name,\n\u001b[0m\u001b[0;32m     61\u001b[0m                                         inputs, attrs, num_outputs)\n\u001b[0;32m     62\u001b[0m   \u001b[1;32mexcept\u001b[0m \u001b[0mcore\u001b[0m\u001b[1;33m.\u001b[0m\u001b[0m_NotOkStatusException\u001b[0m \u001b[1;32mas\u001b[0m \u001b[0me\u001b[0m\u001b[1;33m:\u001b[0m\u001b[1;33m\u001b[0m\u001b[1;33m\u001b[0m\u001b[0m\n",
      "\u001b[1;31mInvalidArgumentError\u001b[0m: Graph execution error:\n\nDetected at node sequential/dense/Relu defined at (most recent call last):\n  File \"C:\\Users\\7240\\anaconda3\\lib\\runpy.py\", line 197, in _run_module_as_main\n\n  File \"C:\\Users\\7240\\anaconda3\\lib\\runpy.py\", line 87, in _run_code\n\n  File \"C:\\Users\\7240\\anaconda3\\lib\\site-packages\\ipykernel_launcher.py\", line 17, in <module>\n\n  File \"C:\\Users\\7240\\anaconda3\\lib\\site-packages\\traitlets\\config\\application.py\", line 846, in launch_instance\n\n  File \"C:\\Users\\7240\\anaconda3\\lib\\site-packages\\ipykernel\\kernelapp.py\", line 712, in start\n\n  File \"C:\\Users\\7240\\anaconda3\\lib\\site-packages\\tornado\\platform\\asyncio.py\", line 199, in start\n\n  File \"C:\\Users\\7240\\anaconda3\\lib\\asyncio\\base_events.py\", line 601, in run_forever\n\n  File \"C:\\Users\\7240\\anaconda3\\lib\\asyncio\\base_events.py\", line 1905, in _run_once\n\n  File \"C:\\Users\\7240\\anaconda3\\lib\\asyncio\\events.py\", line 80, in _run\n\n  File \"C:\\Users\\7240\\anaconda3\\lib\\site-packages\\ipykernel\\kernelbase.py\", line 510, in dispatch_queue\n\n  File \"C:\\Users\\7240\\anaconda3\\lib\\site-packages\\ipykernel\\kernelbase.py\", line 499, in process_one\n\n  File \"C:\\Users\\7240\\anaconda3\\lib\\site-packages\\ipykernel\\kernelbase.py\", line 406, in dispatch_shell\n\n  File \"C:\\Users\\7240\\anaconda3\\lib\\site-packages\\ipykernel\\kernelbase.py\", line 730, in execute_request\n\n  File \"C:\\Users\\7240\\anaconda3\\lib\\site-packages\\ipykernel\\ipkernel.py\", line 390, in do_execute\n\n  File \"C:\\Users\\7240\\anaconda3\\lib\\site-packages\\ipykernel\\zmqshell.py\", line 528, in run_cell\n\n  File \"C:\\Users\\7240\\anaconda3\\lib\\site-packages\\IPython\\core\\interactiveshell.py\", line 2914, in run_cell\n\n  File \"C:\\Users\\7240\\anaconda3\\lib\\site-packages\\IPython\\core\\interactiveshell.py\", line 2960, in _run_cell\n\n  File \"C:\\Users\\7240\\anaconda3\\lib\\site-packages\\IPython\\core\\async_helpers.py\", line 78, in _pseudo_sync_runner\n\n  File \"C:\\Users\\7240\\anaconda3\\lib\\site-packages\\IPython\\core\\interactiveshell.py\", line 3185, in run_cell_async\n\n  File \"C:\\Users\\7240\\anaconda3\\lib\\site-packages\\IPython\\core\\interactiveshell.py\", line 3377, in run_ast_nodes\n\n  File \"C:\\Users\\7240\\anaconda3\\lib\\site-packages\\IPython\\core\\interactiveshell.py\", line 3457, in run_code\n\n  File \"C:\\Users\\7240\\AppData\\Local\\Temp\\ipykernel_6564\\994942145.py\", line 1, in <module>\n\n  File \"C:\\Users\\7240\\AppData\\Local\\Temp\\ipykernel_6564\\3861827433.py\", line 11, in predict_mutiple\n\n  File \"C:\\Users\\7240\\anaconda3\\lib\\site-packages\\keras\\src\\utils\\traceback_utils.py\", line 65, in error_handler\n\n  File \"C:\\Users\\7240\\anaconda3\\lib\\site-packages\\keras\\src\\engine\\training.py\", line 2631, in predict\n\n  File \"C:\\Users\\7240\\anaconda3\\lib\\site-packages\\keras\\src\\engine\\training.py\", line 2416, in predict_function\n\n  File \"C:\\Users\\7240\\anaconda3\\lib\\site-packages\\keras\\src\\engine\\training.py\", line 2401, in step_function\n\n  File \"C:\\Users\\7240\\anaconda3\\lib\\site-packages\\keras\\src\\engine\\training.py\", line 2389, in run_step\n\n  File \"C:\\Users\\7240\\anaconda3\\lib\\site-packages\\keras\\src\\engine\\training.py\", line 2357, in predict_step\n\n  File \"C:\\Users\\7240\\anaconda3\\lib\\site-packages\\keras\\src\\utils\\traceback_utils.py\", line 65, in error_handler\n\n  File \"C:\\Users\\7240\\anaconda3\\lib\\site-packages\\keras\\src\\engine\\training.py\", line 589, in __call__\n\n  File \"C:\\Users\\7240\\anaconda3\\lib\\site-packages\\keras\\src\\utils\\traceback_utils.py\", line 65, in error_handler\n\n  File \"C:\\Users\\7240\\anaconda3\\lib\\site-packages\\keras\\src\\engine\\base_layer.py\", line 1149, in __call__\n\n  File \"C:\\Users\\7240\\anaconda3\\lib\\site-packages\\keras\\src\\utils\\traceback_utils.py\", line 96, in error_handler\n\n  File \"C:\\Users\\7240\\anaconda3\\lib\\site-packages\\keras\\src\\engine\\sequential.py\", line 398, in call\n\n  File \"C:\\Users\\7240\\anaconda3\\lib\\site-packages\\keras\\src\\engine\\functional.py\", line 515, in call\n\n  File \"C:\\Users\\7240\\anaconda3\\lib\\site-packages\\keras\\src\\engine\\functional.py\", line 672, in _run_internal_graph\n\n  File \"C:\\Users\\7240\\anaconda3\\lib\\site-packages\\keras\\src\\utils\\traceback_utils.py\", line 65, in error_handler\n\n  File \"C:\\Users\\7240\\anaconda3\\lib\\site-packages\\keras\\src\\engine\\base_layer.py\", line 1149, in __call__\n\n  File \"C:\\Users\\7240\\anaconda3\\lib\\site-packages\\keras\\src\\utils\\traceback_utils.py\", line 96, in error_handler\n\n  File \"C:\\Users\\7240\\anaconda3\\lib\\site-packages\\keras\\src\\layers\\core\\dense.py\", line 255, in call\n\n  File \"C:\\Users\\7240\\anaconda3\\lib\\site-packages\\keras\\src\\activations.py\", line 306, in relu\n\n  File \"C:\\Users\\7240\\anaconda3\\lib\\site-packages\\keras\\src\\backend.py\", line 5397, in relu\n\nMatrix size-incompatible: In[0]: [32,12544], In[1]: [57600,500]\n\t [[{{node sequential/dense/Relu}}]] [Op:__inference_predict_function_491]"
     ]
    }
   ],
   "source": [
    "predict_mutiple(image_paths_list)"
   ]
  },
  {
   "cell_type": "code",
   "execution_count": null,
   "metadata": {},
   "outputs": [],
   "source": []
  }
 ],
 "metadata": {
  "kernelspec": {
   "display_name": "Python 3 (ipykernel)",
   "language": "python",
   "name": "python3"
  },
  "language_info": {
   "codemirror_mode": {
    "name": "ipython",
    "version": 3
   },
   "file_extension": ".py",
   "mimetype": "text/x-python",
   "name": "python",
   "nbconvert_exporter": "python",
   "pygments_lexer": "ipython3",
   "version": "3.9.13"
  }
 },
 "nbformat": 4,
 "nbformat_minor": 4
}
